<mujoco>
    <worldbody>
        <light diffuse=".5 .5 .5" pos="0 0 5" dir="0 0 -1" />
        <geom type="plane" size="5 5 0.1" rgba=".9 0 0 1" />
        <body name="body0" pos="0 0 1">
            <joint type="free" />
            <geom type="box" size=".1 .2 .3" rgba="0 .9 0 1" />
        </body>
        <body name="body1" pos="-1 -2 4">
            <joint type="free" />
            <geom type="sphere" size=".3" rgba="0 0 0.9 1" />
        </body>
        <body name="body2" pos="-1 -1 1">
            <geom type="box" size="0.1 0.3 0.1" rgba="0.2 0.7 0.5 1" />
            <joint name="joint1" type="hinge" axis="-1 -1 1.5" />
            <body name="body3" pos="-1 0 0">
                <geom type="box" size="0.1 0.3 0.1" rgba="0.2 0.7 0.5 1" />
            </body>
        </body>
        <body name="body4" pos="-2.2 -1.4 0.1">
            <joint type="free" />
            <geom type="box" size="0.1 0.3 0.1" rgba="0.2 0.7 0.5 1" />
        </body>
    </worldbody>
</mujoco>